<?xml version="1.0"?>
<robot xmlns:xacro="http://www.ros.org/wiki/xacro" >

  <material name="Black">
    <color rgba="0 0 0 1" />
  </material>
  <material name="Grey">
    <color rgba="0.8 0.8 0.8 1" />
  </material>
  <material name="Orange">
    <color rgba="1 0.6 0 1" />
  </material>
  <material name="White">
    <color rgba="1 1 1 1" />
  </material>
  <material name="Green">
    <color rgba="0 1 0 1" />
  </material>

  <link name="base_link" />

  <!-- Chassis -->
  <link name="chassis">
    <collision>
      <origin xyz="0 0 0" rpy="0 0 0" />
      <geometry>
        <box size="2 1 0.5" />
      </geometry>
    </collision>

    <visual>
      <origin xyz="0 0 0" rpy="0 0 0" />
      <geometry>
        <box size="2 1 0.5" />
      </geometry>
      <material name="Green" />
    </visual>

    <inertial>
      <origin xyz="0 0 0" rpy="0 0 0" />
      <mass value="1" />
      <inertia ixx="0.126164" ixy="0.0" ixz="0.0" iyy="0.416519" iyz="0.0" izz="0.481014" />
    </inertial>
  </link>

  <joint name="chassis_joint" type="fixed">
    <origin xyz="0.8 0 0.5" rpy="0 0 0" />
    <parent link="base_link" />
    <child link="chassis" />
  </joint>

  <!-- CAR LIGHT -->



<link name="car_light">
</link>

<joint name="car_light_joint" type="fixed">
  <parent link="chassis" />
  <child link="car_light" />
  <origin xyz="0 0 2" rpy="0 0 0" /> <!-- Adjust position above the chassis -->
</joint>

<gazebo reference="car_light">
  <light name="car_point_light" type="point">
    <diffuse>1 1 1 1</diffuse> <!-- White light -->
    <specular>0.5 0.5 0.5 1</specular>
    <attenuation>
      <range>20</range>
      <constant>1.0</constant>
      <linear>0.01</linear>
      <quadratic>0.001</quadratic>
    </attenuation>
    <cast_shadows>true</cast_shadows>
  </light>
</gazebo>



  <!-- rear left wheel Link -->
  <link name="rear_left_wheel">
    <collision>
      <geometry>
        <cylinder length="0.08" radius="0.3" />
      </geometry>
    </collision>
    <visual>
      <geometry>
        <cylinder length="0.08" radius="0.3" />
      </geometry>
      <material name="Black" />
    </visual>

    <inertial>
      <mass value="2" />
      <inertia ixx="0.145833" ixy="0.0" ixz="0.0" iyy="0.145833" iyz="0.0" izz="0.125" />
    </inertial>
  </link>

  <joint name="rear_left_wheel_joint" type="continuous">
    <origin xyz="-0.8 0.5 -0.2" rpy="-1.57 0 0" />
    <parent link="chassis" />
    <child link="rear_left_wheel" />
    <axis xyz="0 0 1" />
    <dynamics damping="0.2" />
  </joint>

  <!-- rear right wheel Link -->
  <link name="rear_right_wheel">
    <collision>
      <geometry>
        <cylinder length="0.08" radius="0.3" />
      </geometry>
    </collision>
    <visual>
      <geometry>
        <cylinder length="0.08" radius="0.3" />
      </geometry>
      <material name="Black" />
    </visual>
    <inertial>
      <mass value="2" />
      <inertia ixx="0.145833" ixy="0.0" ixz="0.0" iyy="0.145833" iyz="0.0" izz="0.125" />
    </inertial>
  </link>

  <joint name="rear_right_wheel_joint" type="continuous">
    <origin xyz="-0.8 -0.5 -0.2" rpy="-1.57 0 0" />
    <parent link="chassis" />
    <child link="rear_right_wheel" />
    <axis xyz="0 0 1" />
    <dynamics damping="0.2" />
  </joint>

  <!-- left steer Link -->
  <link name="left_wheel_steering">
    <inertial>
      <mass value="0.1"/>
      <inertia ixx="0" ixy="0.0" ixz="0.0" iyy="0.0" iyz="0.0" izz="0.0" />
    </inertial>
  </link>

  <joint name="left_wheel_steering_joint" type="continuous">
    <origin xyz="0.9 0.5 -0.2" rpy="-1.57 0 0" />
    <parent link="chassis" />
    <child link="left_wheel_steering" />
    <axis xyz="0 1 0" />
    <dynamics damping="0.2" />
  </joint>

  <!-- right steer Link -->
  <link name="right_wheel_steering">
    <inertial>
      <mass value="0.1"/>
      <inertia ixx="0" ixy="0.0" ixz="0.0" iyy="0.0" iyz="0.0" izz="0.0" />
    </inertial>
  </link>

  <joint name="right_wheel_steering_joint" type="continuous">
    <origin xyz="0.9 -0.5 -0.2" rpy="-1.57 0 0" />
    <parent link="chassis" />
    <child link="right_wheel_steering" />
    <axis xyz="0 1 0" />
    <dynamics damping="0.2" />
  </joint>

  <!-- front left wheel Link -->
  <link name="front_left_wheel">
    <collision>
      <geometry>
        <cylinder length="0.08" radius="0.3" />
      </geometry>
    </collision>
    <visual>
      <geometry>
        <cylinder length="0.08" radius="0.3" />
      </geometry>
      <material name="Black" />
    </visual>
    <inertial>
      <mass value="2" />
      <inertia ixx="0.145833" ixy="0.0" ixz="0.0" iyy="0.145833" iyz="0.0" izz="0.125" />
    </inertial>
  </link>

  <joint name="front_left_wheel_joint" type="continuous">
    <origin xyz="0 0 0" rpy="0 0 0" />
    <parent link="left_wheel_steering" />
    <child link="front_left_wheel" />
    <axis xyz="0 0 1" />
    <dynamics damping="0.2" />
  </joint>

  <!-- front right wheel Link -->
  <link name="front_right_wheel">
    <collision>
      <geometry>
        <cylinder length="0.08" radius="0.3" />
      </geometry>
    </collision>
    <visual>
      <geometry>
        <cylinder length="0.08" radius="0.3" />
      </geometry>
      <material name="Black" />
    </visual>
    <inertial>
      <mass value="2" />
      <inertia ixx="0.145833" ixy="0.0" ixz="0.0" iyy="0.145833" iyz="0.0" izz="0.125" />
    </inertial>
  </link>

  <joint name="front_right_wheel_joint" type="continuous">
    <origin xyz="0 0 0" rpy="0 0 0" />
    <parent link="right_wheel_steering" />
    <child link="front_right_wheel" />
    <axis xyz="0 0 1" />
    <dynamics damping="0.2" />
  </joint>

</robot>
